<?xml version="1.0"?>
<robot xmlns:xacro="http://www.ros.org/wiki/xacro" name="barista_bot">

    <!-- LEFT WHEEL LINK -->
    <joint name="left_wheel_joint" type="continuous">
        <parent link="base_link"/>
        <child link="left_wheel"/>
        <origin xyz="0 0.15 -0.0775" rpy="-1.57 0 0" />
        <axis xyz="0 0 1"/>
    </joint>

    <link name="left_wheel">
        <inertial>
            <mass value="1.5" />
            <origin xyz="0 0 0" rpy="-1.57 0 0" />
            <inertia ixx=" 0.000517685" ixy="0.0" ixz="0.0" iyy= "0.000517685" iyz="0.0" izz="0.00092928" />
        </inertial>
        <visual>
            <origin xyz="0 0 0" rpy="0 0 0"/>
            <geometry>
                <cylinder radius="0.0352" length="0.0206"/>
            </geometry>
            <material name="black"/>
        </visual>
        <collision>
            <origin xyz="0 0 0" rpy="0 0 0"/>
            <geometry>
                <cylinder radius="0.0352" length="0.0206"/>
            </geometry>
        </collision>
    </link>


    <!-- RIGHT WHEEL LINK -->

    <joint name="right_wheel_joint" type="continuous">
        <parent link="base_link"/>
        <child link="right_wheel"/>
        <origin xyz="0 -0.15 -0.0775" rpy="1.57 0 0" />
        <axis xyz="0 0 -1"/>
    </joint>

    <link name="right_wheel">
        <inertial>
            <mass value="1.5" />
            <origin xyz="0 0 0" rpy="-1.575 0 0" />
        <inertia ixx=" 0.000517685" ixy="0.0" ixz="0.0" iyy= "0.000517685" iyz="0.0" izz="0.00092928" />
        </inertial>
        <visual>
            <origin xyz="0 0 0" rpy="0 0 0"/>
            <geometry>
                <cylinder radius="0.0352" length="0.0206"/>
            </geometry>
            <material name="black"/>
        </visual>
        <collision>
            <origin xyz="0 0 0" rpy="0 0 0"/>
            <geometry>
                <cylinder radius="0.0352" length="0.0206"/>
            </geometry>
        </collision>
    </link>
</robot>


