<?xml version="1.0"?>
<robot name="barista_bot">

  <material name="red">
      <color rgba="1.0 0.0 0.0 1"/>
  </material>

  <material name="green_light">
      <color rgba="0.0 1.0 0.0 1"/>
  </material>

  <material name="green_dark">
    <color rgba="0.0 0.5 0.0 1"/>
  </material>

  <material name="blue">
      <color rgba="0.0 0.0 1.0 1"/>
  </material>

  <material name="black">
      <color rgba="0.0 0.0 0.0 1"/>
  </material>

  <material name="white">
      <color rgba="1.0 1.0 1.0 1"/>
  </material>

  <link name="base_link">
  </link>


  <!-- Main Body -->
  <link name="main_body">
    <visual>
      <geometry>
        <cylinder length="0.155" radius="0.1825"/>
      </geometry>
      <material name="blue"/>
    </visual>
  </link>

  <joint name="base_body_joint" type="fixed">
    <origin rpy="0 0 0" xyz="0 0 .1127" />
    <parent link="base_link" />
    <child link="main_body" />
  </joint>

  <!-- Wheel Left -->
  <link name="left_wheel">      
      <visual>
        <origin rpy="1.5707 0 0" xyz="0 0 0"/>
        <geometry>
          <cylinder length="0.0206" radius="0.0352"/>
        </geometry>
        <material name="black"/>
      </visual>
  </link>


  <joint name="joint_left_wheel" type="continuous">
    <origin rpy="0 0 0" xyz="0 0.150 -0.0352"/>
    <child link="left_wheel"/>
    <parent link="main_body"/>
    <axis rpy="0 0 0" xyz="0 1 0"/>
    <limit effort="10000" velocity="1000"/>

  </joint>

</robot>